[2018-05-06 09:58:05,843] ERROR: execute task failed... [in D:\Projects\atPC\mlpm-jobs\tasks\core.py:18 on_failure]
Traceback (most recent call last):
  File "d:\projects\atpc\mlpm-jobs\venv\lib\site-packages\pyspark\sql\utils.py", line 63, in deco
    return f(*a, **kw)
  File "d:\projects\atpc\mlpm-jobs\venv\lib\site-packages\py4j\protocol.py", line 320, in get_return_value
    format(target_id, ".", name), value)
py4j.protocol.Py4JJavaError: An error occurred while calling o27.text.
: java.lang.IllegalArgumentException: Wrong FS: file://D:\Projects\atPC\mlpm-jobs\alembic.ini/D:/Projects/atPC/mlpm-jobs, expected: file:///
	at org.apache.hadoop.fs.FileSystem.checkPath(FileSystem.java:649)
	at org.apache.hadoop.fs.RawLocalFileSystem.pathToFile(RawLocalFileSystem.java:82)
	at org.apache.hadoop.fs.RawLocalFileSystem.deprecatedGetFileStatus(RawLocalFileSystem.java:606)
	at org.apache.hadoop.fs.RawLocalFileSystem.getFileLinkStatusInternal(RawLocalFileSystem.java:824)
	at org.apache.hadoop.fs.RawLocalFileSystem.getFileStatus(RawLocalFileSystem.java:601)
	at org.apache.hadoop.fs.FilterFileSystem.getFileStatus(FilterFileSystem.java:421)
	at org.apache.hadoop.fs.Globber.getFileStatus(Globber.java:57)
	at org.apache.hadoop.fs.Globber.glob(Globber.java:252)
	at org.apache.hadoop.fs.FileSystem.globStatus(FileSystem.java:1657)
	at org.apache.spark.deploy.SparkHadoopUtil.globPath(SparkHadoopUtil.scala:242)
	at org.apache.spark.deploy.SparkHadoopUtil.globPathIfNecessary(SparkHadoopUtil.scala:252)
	at org.apache.spark.sql.execution.datasources.DataSource$.org$apache$spark$sql$execution$datasources$DataSource$$checkAndGlobPathIfNecessary(DataSource.scala:707)
	at org.apache.spark.sql.execution.datasources.DataSource$$anonfun$15.apply(DataSource.scala:389)
	at org.apache.spark.sql.execution.datasources.DataSource$$anonfun$15.apply(DataSource.scala:389)
	at scala.collection.TraversableLike$$anonfun$flatMap$1.apply(TraversableLike.scala:241)
	at scala.collection.TraversableLike$$anonfun$flatMap$1.apply(TraversableLike.scala:241)
	at scala.collection.immutable.List.foreach(List.scala:381)
	at scala.collection.TraversableLike$class.flatMap(TraversableLike.scala:241)
	at scala.collection.immutable.List.flatMap(List.scala:344)
	at org.apache.spark.sql.execution.datasources.DataSource.resolveRelation(DataSource.scala:388)
	at org.apache.spark.sql.DataFrameReader.loadV1Source(DataFrameReader.scala:239)
	at org.apache.spark.sql.DataFrameReader.load(DataFrameReader.scala:227)
	at org.apache.spark.sql.DataFrameReader.text(DataFrameReader.scala:691)
	at sun.reflect.NativeMethodAccessorImpl.invoke0(Native Method)
	at sun.reflect.NativeMethodAccessorImpl.invoke(NativeMethodAccessorImpl.java:62)
	at sun.reflect.DelegatingMethodAccessorImpl.invoke(DelegatingMethodAccessorImpl.java:43)
	at java.lang.reflect.Method.invoke(Method.java:498)
	at py4j.reflection.MethodInvoker.invoke(MethodInvoker.java:244)
	at py4j.reflection.ReflectionEngine.invoke(ReflectionEngine.java:357)
	at py4j.Gateway.invoke(Gateway.java:282)
	at py4j.commands.AbstractCommand.invokeMethod(AbstractCommand.java:132)
	at py4j.commands.CallCommand.execute(CallCommand.java:79)
	at py4j.GatewayConnection.run(GatewayConnection.java:214)
	at java.lang.Thread.run(Thread.java:745)


During handling of the above exception, another exception occurred:

Traceback (most recent call last):
  File "d:\projects\atpc\mlpm-jobs\venv\lib\site-packages\celery\app\trace.py", line 367, in trace_task
    R = retval = fun(*args, **kwargs)
  File "d:\projects\atpc\mlpm-jobs\venv\lib\site-packages\celery\app\trace.py", line 622, in __protected_call__
    return self.run(*args, **kwargs)
  File "D:\Projects\atPC\mlpm-jobs\tasks\general\example.py", line 49, in spark_word_count
    lines = spark.read.text(file_path).rdd.map(lambda r: r[0])
  File "d:\projects\atpc\mlpm-jobs\venv\lib\site-packages\pyspark\sql\readwriter.py", line 328, in text
    return self._df(self._jreader.text(self._spark._sc._jvm.PythonUtils.toSeq(paths)))
  File "d:\projects\atpc\mlpm-jobs\venv\lib\site-packages\py4j\java_gateway.py", line 1160, in __call__
    answer, self.gateway_client, self.target_id, self.name)
  File "d:\projects\atpc\mlpm-jobs\venv\lib\site-packages\pyspark\sql\utils.py", line 79, in deco
    raise IllegalArgumentException(s.split(': ', 1)[1], stackTrace)
pyspark.sql.utils.IllegalArgumentException: 'Wrong FS: file://D:\\Projects\\atPC\\mlpm-jobs\\alembic.ini/D:/Projects/atPC/mlpm-jobs, expected: file:///'
